<?xml version="1.0" ?>
<!-- =================================================================================== -->
<!-- |    This document was autogenerated by xacro from HBV2_URDF.xacro                | -->
<!-- |    EDITING THIS FILE BY HAND IS NOT RECOMMENDED                                 | -->
<!-- =================================================================================== -->
<robot name="HBV2_URDF">
  <material name="silver">
    <color rgba="0.700 0.700 0.700 1.000"/>
  </material>
  <transmission name="Elbow_Theta_tran">
    <type>transmission_interface/SimpleTransmission</type>
    <joint name="Elbow_Theta">
      <hardwareInterface>hardware_interface/PositionJointInterface</hardwareInterface>
    </joint>
    <actuator name="Elbow_Theta_actr">
      <hardwareInterface>hardware_interface/PositionJointInterface</hardwareInterface>
      <mechanicalReduction>1</mechanicalReduction>
    </actuator>
  </transmission>
  <transmission name="Wrist_Theta_tran">
    <type>transmission_interface/SimpleTransmission</type>
    <joint name="Wrist_Theta">
      <hardwareInterface>hardware_interface/PositionJointInterface</hardwareInterface>
    </joint>
    <actuator name="Wrist_Theta_actr">
      <hardwareInterface>hardware_interface/PositionJointInterface</hardwareInterface>
      <mechanicalReduction>1</mechanicalReduction>
    </actuator>
  </transmission>
  <transmission name="Shoulder_Theta_Joint_tran">
    <type>transmission_interface/SimpleTransmission</type>
    <joint name="Shoulder_Theta_Joint">
      <hardwareInterface>hardware_interface/PositionJointInterface</hardwareInterface>
    </joint>
    <actuator name="Shoulder_Theta_Joint_actr">
      <hardwareInterface>hardware_interface/PositionJointInterface</hardwareInterface>
      <mechanicalReduction>1</mechanicalReduction>
    </actuator>
  </transmission>
  <transmission name="GCore_RSL_tran">
    <type>transmission_interface/SimpleTransmission</type>
    <joint name="GCore_RSL">
      <hardwareInterface>hardware_interface/PositionJointInterface</hardwareInterface>
    </joint>
    <actuator name="GCore_RSL_actr">
      <hardwareInterface>hardware_interface/PositionJointInterface</hardwareInterface>
      <mechanicalReduction>1</mechanicalReduction>
    </actuator>
  </transmission>
  <transmission name="RSL_RightProng_tran">
    <type>transmission_interface/SimpleTransmission</type>
    <joint name="RSL_RightProng">
      <hardwareInterface>hardware_interface/PositionJointInterface</hardwareInterface>
    </joint>
    <actuator name="RSL_RightProng_actr">
      <hardwareInterface>hardware_interface/PositionJointInterface</hardwareInterface>
      <mechanicalReduction>1</mechanicalReduction>
    </actuator>
  </transmission>
  <transmission name="LSL_LeftProng_tran">
    <type>transmission_interface/SimpleTransmission</type>
    <joint name="LSL_LeftProng">
      <hardwareInterface>hardware_interface/PositionJointInterface</hardwareInterface>
    </joint>
    <actuator name="LSL_LeftProng_actr">
      <hardwareInterface>hardware_interface/PositionJointInterface</hardwareInterface>
      <mechanicalReduction>1</mechanicalReduction>
    </actuator>
  </transmission>
  <transmission name="GCore_LSL_tran">
    <type>transmission_interface/SimpleTransmission</type>
    <joint name="GCore_LSL">
      <hardwareInterface>hardware_interface/PositionJointInterface</hardwareInterface>
    </joint>
    <actuator name="GCore_LSL_actr">
      <hardwareInterface>hardware_interface/PositionJointInterface</hardwareInterface>
      <mechanicalReduction>1</mechanicalReduction>
    </actuator>
  </transmission>
  <transmission name="Base_WheelRF_tran">
    <type>transmission_interface/SimpleTransmission</type>
    <joint name="Base_WheelRF">
      <hardwareInterface>hardware_interface/VelocityJointInterface</hardwareInterface>
    </joint>
    <actuator name="Base_WheelRF_actr">
      <hardwareInterface>hardware_interface/VelocityJointInterface</hardwareInterface>
      <mechanicalReduction>1</mechanicalReduction>
    </actuator>
  </transmission>
  <transmission name="Base_WheelLF_tran">
    <type>transmission_interface/SimpleTransmission</type>
    <joint name="Base_WheelLF">
      <hardwareInterface>hardware_interface/VelocityJointInterface</hardwareInterface>
    </joint>
    <actuator name="Base_WheelLF_actr">
      <hardwareInterface>hardware_interface/VelocityJointInterface</hardwareInterface>
      <mechanicalReduction>1</mechanicalReduction>
    </actuator>
  </transmission>
  <transmission name="Base_WheelRB_tran">
    <type>transmission_interface/SimpleTransmission</type>
    <joint name="Base_WheelRB">
      <hardwareInterface>hardware_interface/VelocityJointInterface</hardwareInterface>
    </joint>
    <actuator name="Base_WheelRB_actr">
      <hardwareInterface>hardware_interface/VelocityJointInterface</hardwareInterface>
      <mechanicalReduction>1</mechanicalReduction>
    </actuator>
  </transmission>
  <transmission name="Base_WheelLB_tran">
    <type>transmission_interface/SimpleTransmission</type>
    <joint name="Base_WheelLB">
      <hardwareInterface>hardware_interface/VelocityJointInterface</hardwareInterface>
    </joint>
    <actuator name="Base_WheelLB_actr">
      <hardwareInterface>hardware_interface/VelocityJointInterface</hardwareInterface>
      <mechanicalReduction>1</mechanicalReduction>
    </actuator>
  </transmission>
  <transmission name="Shoulder_Fi_tran">
    <type>transmission_interface/SimpleTransmission</type>
    <joint name="Shoulder_Fi">
      <hardwareInterface>hardware_interface/PositionJointInterface</hardwareInterface>
    </joint>
    <actuator name="Shoulder_Fi_actr">
      <hardwareInterface>hardware_interface/PositionJointInterface</hardwareInterface>
      <mechanicalReduction>1</mechanicalReduction>
    </actuator>
  </transmission>
  <transmission name="Elbow_Fi_tran">
    <type>transmission_interface/SimpleTransmission</type>
    <joint name="Elbow_Fi">
      <hardwareInterface>hardware_interface/PositionJointInterface</hardwareInterface>
    </joint>
    <actuator name="Elbow_Fi_actr">
      <hardwareInterface>hardware_interface/PositionJointInterface</hardwareInterface>
      <mechanicalReduction>1</mechanicalReduction>
    </actuator>
  </transmission>
  <transmission name="Wrist_Fi_tran">
    <type>transmission_interface/SimpleTransmission</type>
    <joint name="Wrist_Fi">
      <hardwareInterface>hardware_interface/PositionJointInterface</hardwareInterface>
    </joint>
    <actuator name="Wrist_Fi_actr">
      <hardwareInterface>hardware_interface/PositionJointInterface</hardwareInterface>
      <mechanicalReduction>1</mechanicalReduction>
    </actuator>
  </transmission>
  <gazebo>
    <plugin filename="libgazebo_ros_control.so" name="control"/>
  </gazebo>
  <gazebo reference="base_link">
    <material>Gazebo/Silver</material>
    <mu1>0.2</mu1>
    <mu2>0.2</mu2>
    <selfCollide>true</selfCollide>
    <gravity>true</gravity>
  </gazebo>
  <gazebo reference="Elbow_Fi_1">
    <material>Gazebo/Silver</material>
    <mu1>0.2</mu1>
    <mu2>0.2</mu2>
    <selfCollide>true</selfCollide>
  </gazebo>
  <gazebo reference="Wrist_Fi_1">
    <material>Gazebo/Silver</material>
    <mu1>0.2</mu1>
    <mu2>0.2</mu2>
    <selfCollide>true</selfCollide>
  </gazebo>
  <gazebo reference="Shoulder_Theta_1">
    <material>Gazebo/Silver</material>
    <mu1>0.2</mu1>
    <mu2>0.2</mu2>
    <selfCollide>true</selfCollide>
  </gazebo>
  <gazebo reference="Shoulder_Fi_1">
    <material>Gazebo/Silver</material>
    <mu1>0.2</mu1>
    <mu2>0.2</mu2>
    <selfCollide>true</selfCollide>
  </gazebo>
  <gazebo reference="RSL__1__1">
    <material>Gazebo/Silver</material>
    <mu1>0.2</mu1>
    <mu2>0.2</mu2>
    <selfCollide>true</selfCollide>
  </gazebo>
  <gazebo reference="RightProng__1__1">
    <material>Gazebo/Silver</material>
    <mu1>0.2</mu1>
    <mu2>0.2</mu2>
    <selfCollide>true</selfCollide>
  </gazebo>
  <gazebo reference="LeftProng__2__1">
    <material>Gazebo/Silver</material>
    <mu1>0.2</mu1>
    <mu2>0.2</mu2>
    <selfCollide>true</selfCollide>
  </gazebo>
  <gazebo reference="LSL__3__1">
    <material>Gazebo/Silver</material>
    <mu1>0.2</mu1>
    <mu2>0.2</mu2>
    <selfCollide>true</selfCollide>
  </gazebo>
  <gazebo reference="Wheel_RF_1">
    <material>Gazebo/Silver</material>
    <mu1>0.2</mu1>
    <mu2>0.2</mu2>
    <selfCollide>true</selfCollide>
  </gazebo>
  <gazebo reference="Wheel_LF_1">
    <material>Gazebo/Silver</material>
    <mu1>0.2</mu1>
    <mu2>0.2</mu2>
    <selfCollide>true</selfCollide>
  </gazebo>
  <gazebo reference="Wheel_RB_1">
    <material>Gazebo/Silver</material>
    <mu1>0.2</mu1>
    <mu2>0.2</mu2>
    <selfCollide>true</selfCollide>
  </gazebo>
  <gazebo reference="Wheel_LB_1">
    <material>Gazebo/Silver</material>
    <mu1>0.2</mu1>
    <mu2>0.2</mu2>
    <selfCollide>true</selfCollide>
  </gazebo>
  <gazebo reference="Camera_Rod__1__1">
    <material>Gazebo/Silver</material>
    <mu1>0.2</mu1>
    <mu2>0.2</mu2>
    <selfCollide>true</selfCollide>
  </gazebo>
  <gazebo reference="Camera_Housing_1">
    <material>Gazebo/Silver</material>
    <mu1>0.2</mu1>
    <mu2>0.2</mu2>
    <selfCollide>true</selfCollide>
  </gazebo>
  <gazebo reference="Elbow_Theta_1">
    <material>Gazebo/Silver</material>
    <mu1>0.2</mu1>
    <mu2>0.2</mu2>
    <selfCollide>true</selfCollide>
  </gazebo>
  <gazebo reference="Wrist_Theta_1">
    <material>Gazebo/Silver</material>
    <mu1>0.2</mu1>
    <mu2>0.2</mu2>
    <selfCollide>true</selfCollide>
  </gazebo>
  <gazebo reference="Gripper_Core_1">
    <material>Gazebo/Silver</material>
    <mu1>0.2</mu1>
    <mu2>0.2</mu2>
    <selfCollide>true</selfCollide>
  </gazebo>
  <!--
  <link name="world"/>
  <joint name="virtual_joint" type="fixed">
    <origin rpy="0 0 0" xyz="0 0 0"/>
    <parent link="world"/>
    <child link="base_link"/>
  </joint>
-->
  <link name="base_link">
    <inertial>
      <origin rpy="0 0 0" xyz="0.000850703825743988 0.49664524660197173 0.1431193454180441"/>
      <mass value="83.16735088772546"/>
      <inertia ixx="2.05207" ixy="-0.008757" ixz="0.001707" iyy="3.182622" iyz="0.00132" izz="4.445124"/>
    </inertial>
    <visual>
      <origin rpy="0 0 0" xyz="0 0 0"/>
      <geometry>
        <mesh filename="package://HBV2_URDF_description/meshes/base_link.stl" scale="0.001 0.001 0.001"/>
      </geometry>
      <material name="silver"/>
    </visual>
    <collision>
      <origin rpy="0 0 0" xyz="0 0 0"/>
      <geometry>
        <mesh filename="package://HBV2_URDF_description/meshes/base_link.stl" scale="0.001 0.001 0.001"/>
      </geometry>
    </collision>
  </link>
  <link name="Elbow_Fi_1">
    <inertial>
      <origin rpy="0 0 0" xyz="2.1124811195401185e-05 -0.004476902241319081 0.04500687296019246"/>
      <mass value="2.6957216092371197"/>
      <inertia ixx="0.007517" ixy="-2e-06" ixz="-4e-06" iyy="0.004928" iyz="0.000521" izz="0.005378"/>
    </inertial>
    <visual>
      <origin rpy="0 0 0" xyz="-0.001635 -0.496054 -0.667865"/>
      <geometry>
        <mesh filename="package://HBV2_URDF_description/meshes/Elbow_Fi_1.stl" scale="0.001 0.001 0.001"/>
      </geometry>
      <material name="silver"/>
    </visual>
    <collision>
      <origin rpy="0 0 0" xyz="-0.001635 -0.496054 -0.667865"/>
      <geometry>
        <mesh filename="package://HBV2_URDF_description/meshes/Elbow_Fi_1.stl" scale="0.001 0.001 0.001"/>
      </geometry>
    </collision>
  </link>
  <link name="Wrist_Fi_1">
    <inertial>
      <origin rpy="0 0 0" xyz="3.808198436288019e-05 -0.003748542098453378 0.042775550119039774"/>
      <mass value="2.1119426583573655"/>
      <inertia ixx="0.004759" ixy="-3e-06" ixz="-3e-06" iyy="0.003093" iyz="0.000293" izz="0.003312"/>
    </inertial>
    <visual>
      <origin rpy="0 0 0" xyz="-0.001635 -0.502604 -0.975809"/>
      <geometry>
        <mesh filename="package://HBV2_URDF_description/meshes/Wrist_Fi_1.stl" scale="0.001 0.001 0.001"/>
      </geometry>
      <material name="silver"/>
    </visual>
    <collision>
      <origin rpy="0 0 0" xyz="-0.001635 -0.502604 -0.975809"/>
      <geometry>
        <mesh filename="package://HBV2_URDF_description/meshes/Wrist_Fi_1.stl" scale="0.001 0.001 0.001"/>
      </geometry>
    </collision>
  </link>
  <link name="Shoulder_Theta_1">
    <inertial>
      <origin rpy="0 0 0" xyz="-0.09893520482510751 5.81749154230371e-05 0.04088469510241685"/>
      <mass value="24.00560665158243"/>
      <inertia ixx="0.187102" ixy="0.000137" ixz="0.012323" iyy="0.417351" iyz="-9.7e-05" izz="0.523776"/>
    </inertial>
    <visual>
      <origin rpy="0 0 0" xyz="-0.001635 -0.496054 -0.246551"/>
      <geometry>
        <mesh filename="package://HBV2_URDF_description/meshes/Shoulder_Theta_1.stl" scale="0.001 0.001 0.001"/>
      </geometry>
      <material name="silver"/>
    </visual>
    <collision>
      <origin rpy="0 0 0" xyz="-0.001635 -0.496054 -0.246551"/>
      <geometry>
        <mesh filename="package://HBV2_URDF_description/meshes/Shoulder_Theta_1.stl" scale="0.001 0.001 0.001"/>
      </geometry>
    </collision>
  </link>
  <link name="Shoulder_Fi_1">
    <inertial>
      <origin rpy="0 0 0" xyz="2.233815221067809e-05 -0.00012306065436118452 0.03488942876530954"/>
      <mass value="6.6711474057675115"/>
      <inertia ixx="0.026216" ixy="-0.0" ixz="-1.5e-05" iyy="0.021888" iyz="4.9e-05" izz="0.027122"/>
    </inertial>
    <visual>
      <origin rpy="0 0 0" xyz="-0.001635 -0.496054 -0.318719"/>
      <geometry>
        <mesh filename="package://HBV2_URDF_description/meshes/Shoulder_Fi_1.stl" scale="0.001 0.001 0.001"/>
      </geometry>
      <material name="silver"/>
    </visual>
    <collision>
      <origin rpy="0 0 0" xyz="-0.001635 -0.496054 -0.318719"/>
      <geometry>
        <mesh filename="package://HBV2_URDF_description/meshes/Shoulder_Fi_1.stl" scale="0.001 0.001 0.001"/>
      </geometry>
    </collision>
  </link>
  <link name="RSL__1__1">
    <inertial>
      <origin rpy="0 0 0" xyz="-0.00602072788649264 0.0004602032959704072 0.01213633179737239"/>
      <mass value="0.028211625634964734"/>
      <inertia ixx="0.001" ixy="0.001" ixz="0.001" iyy="0.01" iyz="-0.001" izz="0.001"/>
    </inertial>
    <visual>
      <origin rpy="0 0 0" xyz="0.012465 -0.489604 -1.149476"/>
      <geometry>
        <mesh filename="package://HBV2_URDF_description/meshes/RSL__1__1.stl" scale="0.001 0.001 0.001"/>
      </geometry>
      <material name="silver"/>
    </visual>
    <collision>
      <origin rpy="0 0 0" xyz="0.012465 -0.489604 -1.149476"/>
      <geometry>
        <mesh filename="package://HBV2_URDF_description/meshes/RSL__1__1.stl" scale="0.001 0.001 0.001"/>
      </geometry>
    </collision>
  </link>
  <link name="RightProng__1__1">
    <inertial>
      <origin rpy="0 0 0" xyz="0.01500020886022858 -0.00934695725623802 0.03142613696884822"/>
      <mass value="0.618571467723155"/>
      <inertia ixx="0.001" ixy="-0.001" ixz="-0.001" iyy="0.001" iyz="-0.001" izz="0.001"/>
    </inertial>
    <visual>
      <origin rpy="0 0 0" xyz="0.012665 -0.494919 -1.187076"/>
      <geometry>
        <mesh filename="package://HBV2_URDF_description/meshes/RightProng__1__1.stl" scale="0.001 0.001 0.001"/>
      </geometry>
      <material name="silver"/>
    </visual>
    <collision>
      <origin rpy="0 0 0" xyz="0.012665 -0.494919 -1.187076"/>
      <geometry>
        <mesh filename="package://HBV2_URDF_description/meshes/RightProng__1__1.stl" scale="0.001 0.001 0.001"/>
      </geometry>
    </collision>
  </link>
  <link name="LeftProng__2__1">
    <inertial>
      <origin rpy="0 0 0" xyz="0.015000208860241815 0.009341259465312834 0.031406978994162005"/>
      <mass value="0.6189487887088181"/>
      <inertia ixx="0.001" ixy="-0.001" ixz="-0.001" iyy="0.001" iyz="0.001" izz="0.001"/>
    </inertial>
    <visual>
      <origin rpy="0 0 0" xyz="0.012665 -0.514289 -1.187076"/>
      <geometry>
        <mesh filename="package://HBV2_URDF_description/meshes/LeftProng__2__1.stl" scale="0.001 0.001 0.001"/>
      </geometry>
      <material name="silver"/>
    </visual>
    <collision>
      <origin rpy="0 0 0" xyz="0.012665 -0.514289 -1.187076"/>
      <geometry>
        <mesh filename="package://HBV2_URDF_description/meshes/LeftProng__2__1.stl" scale="0.001 0.001 0.001"/>
      </geometry>
    </collision>
  </link>
  <link name="LSL__3__1">
    <inertial>
      <origin rpy="0 0 0" xyz="-0.006020728028839378 -0.00046019628870652696 0.012136325015627225"/>
      <mass value="0.028211647703611422"/>
      <inertia ixx="0.001" ixy="-0.001" ixz="0.001" iyy="0.001" iyz="0.001" izz="0.001"/>
    </inertial>
    <visual>
      <origin rpy="0 0 0" xyz="0.012465 -0.519604 -1.149476"/>
      <geometry>
        <mesh filename="package://HBV2_URDF_description/meshes/LSL__3__1.stl" scale="0.001 0.001 0.001"/>
      </geometry>
      <material name="silver"/>
    </visual>
    <collision>
      <origin rpy="0 0 0" xyz="0.012465 -0.519604 -1.149476"/>
      <geometry>
        <mesh filename="package://HBV2_URDF_description/meshes/LSL__3__1.stl" scale="0.001 0.001 0.001"/>
      </geometry>
    </collision>
  </link>
  <link name="Wheel_RF_1">
    <inertial>
      <origin rpy="0 0 0" xyz="1.0816852191730675e-08 -0.02075000000044916 2.772021913399758e-07"/>
      <mass value="21.410160340290883"/>
      <inertia ixx="0.079808" ixy="-0.0" ixz="0.0" iyy="0.140288" iyz="0.0" izz="0.079808"/>
    </inertial>
    <visual>
      <origin rpy="0 0 0" xyz="-0.178899 -0.266079 -0.114299"/>
      <geometry>
        <mesh filename="package://HBV2_URDF_description/meshes/Wheel_RF_1.stl" scale="0.001 0.001 0.001"/>
      </geometry>
      <material name="silver"/>
    </visual>
    <collision>
      <origin rpy="0 0 0" xyz="-0.178899 -0.266079 -0.114299"/>
      <geometry>
        <mesh filename="package://HBV2_URDF_description/meshes/Wheel_RF_1.stl" scale="0.001 0.001 0.001"/>
      </geometry>
    </collision>
  </link>
  <link name="Wheel_LF_1">
    <inertial>
      <origin rpy="0 0 0" xyz="1.0816852247241826e-08 0.0207499999995574 2.772021904656752e-07"/>
      <mass value="21.410160340290883"/>
      <inertia ixx="0.079808" ixy="-0.0" ixz="0.0" iyy="0.140288" iyz="0.0" izz="0.079808"/>
    </inertial>
    <visual>
      <origin rpy="0 0 0" xyz="-0.178899 -0.726029 -0.114299"/>
      <geometry>
        <mesh filename="package://HBV2_URDF_description/meshes/Wheel_LF_1.stl" scale="0.001 0.001 0.001"/>
      </geometry>
      <material name="silver"/>
    </visual>
    <collision>
      <origin rpy="0 0 0" xyz="-0.178899 -0.726029 -0.114299"/>
      <geometry>
        <mesh filename="package://HBV2_URDF_description/meshes/Wheel_LF_1.stl" scale="0.001 0.001 0.001"/>
      </geometry>
    </collision>
  </link>
  <link name="Wheel_RB_1">
    <inertial>
      <origin rpy="0 0 0" xyz="4.974939914748067e-07 -0.020750000000448382 2.7720219129834245e-07"/>
      <mass value="21.410160340290883"/>
      <inertia ixx="0.079808" ixy="-0.0" ixz="0.0" iyy="0.140288" iyz="-0.0" izz="0.079808"/>
    </inertial>
    <visual>
      <origin rpy="0 0 0" xyz="0.175629 -0.266079 -0.114299"/>
      <geometry>
        <mesh filename="package://HBV2_URDF_description/meshes/Wheel_RB_1.stl" scale="0.001 0.001 0.001"/>
      </geometry>
      <material name="silver"/>
    </visual>
    <collision>
      <origin rpy="0 0 0" xyz="0.175629 -0.266079 -0.114299"/>
      <geometry>
        <mesh filename="package://HBV2_URDF_description/meshes/Wheel_RB_1.stl" scale="0.001 0.001 0.001"/>
      </geometry>
    </collision>
  </link>
  <link name="Wheel_LB_1">
    <inertial>
      <origin rpy="0 0 0" xyz="4.974939914470511e-07 0.020749999999557622 2.772021902019972e-07"/>
      <mass value="21.410160340290883"/>
      <inertia ixx="0.079808" ixy="-0.0" ixz="0.0" iyy="0.140288" iyz="-0.0" izz="0.079808"/>
    </inertial>
    <visual>
      <origin rpy="0 0 0" xyz="0.175629 -0.726029 -0.114299"/>
      <geometry>
        <mesh filename="package://HBV2_URDF_description/meshes/Wheel_LB_1.stl" scale="0.001 0.001 0.001"/>
      </geometry>
      <material name="silver"/>
    </visual>
    <collision>
      <origin rpy="0 0 0" xyz="0.175629 -0.726029 -0.114299"/>
      <geometry>
        <mesh filename="package://HBV2_URDF_description/meshes/Wheel_LB_1.stl" scale="0.001 0.001 0.001"/>
      </geometry>
    </collision>
  </link>
  <link name="Camera_Rod__1__1">
    <inertial>
      <origin rpy="0 0 0" xyz="-4.99966369915672e-07 -1.0508501291361938e-09 0.19999953386361996"/>
      <mass value="1.327380701446504"/>
      <inertia ixx="0.017743" ixy="-0.0" ixz="0.0" iyy="0.017743" iyz="0.0" izz="8.9e-05"/>
    </inertial>
    <visual>
      <origin rpy="0 0 0" xyz="0.315312 -0.496055 -0.252951"/>
      <geometry>
        <mesh filename="package://HBV2_URDF_description/meshes/Camera_Rod__1__1.stl" scale="0.001 0.001 0.001"/>
      </geometry>
      <material name="silver"/>
    </visual>
    <collision>
      <origin rpy="0 0 0" xyz="0.315312 -0.496055 -0.252951"/>
      <geometry>
        <mesh filename="package://HBV2_URDF_description/meshes/Camera_Rod__1__1.stl" scale="0.001 0.001 0.001"/>
      </geometry>
    </collision>
  </link>
  <link name="Camera_Housing_1">
    <inertial>
      <origin rpy="0 0 0" xyz="-0.0010156886248149921 3.0852436220807355e-06 0.00711860710983836"/>
      <mass value="1.3677782029205452"/>
      <inertia ixx="0.00192" ixy="-0.0" ixz="1.3e-05" iyy="0.000885" iyz="-0.0" izz="0.001671"/>
    </inertial>
    <visual>
      <origin rpy="0 0 0" xyz="0.315312 -0.496055 -0.652951"/>
      <geometry>
        <mesh filename="package://HBV2_URDF_description/meshes/Camera_Housing_1.stl" scale="0.001 0.001 0.001"/>
      </geometry>
      <material name="silver"/>
    </visual>
    <collision>
      <origin rpy="0 0 0" xyz="0.315312 -0.496055 -0.652951"/>
      <geometry>
        <mesh filename="package://HBV2_URDF_description/meshes/Camera_Housing_1.stl" scale="0.001 0.001 0.001"/>
      </geometry>
    </collision>
  </link>
  <link name="Elbow_Theta_1">
    <inertial>
      <origin rpy="0 0 0" xyz="5.025678449546841e-06 0.028944188172434826 0.09816588851369912"/>
      <mass value="11.80726031614154"/>
      <inertia ixx="0.095065" ixy="2e-06" ixz="-5e-06" iyy="0.089799" iyz="-0.001031" izz="0.043575"/>
    </inertial>
    <visual>
      <origin rpy="0 0 0" xyz="-0.001635 -0.468554 -0.409273"/>
      <geometry>
        <mesh filename="package://HBV2_URDF_description/meshes/Elbow_Theta_1.stl" scale="0.001 0.001 0.001"/>
      </geometry>
      <material name="silver"/>
    </visual>
    <collision>
      <origin rpy="0 0 0" xyz="-0.001635 -0.468554 -0.409273"/>
      <geometry>
        <mesh filename="package://HBV2_URDF_description/meshes/Elbow_Theta_1.stl" scale="0.001 0.001 0.001"/>
      </geometry>
    </collision>
  </link>
  <link name="Wrist_Theta_1">
    <inertial>
      <origin rpy="0 0 0" xyz="-3.840368737391929e-06 -0.05148249173289887 0.0806903784476557"/>
      <mass value="9.499760886023896"/>
      <inertia ixx="0.061147" ixy="2e-06" ixz="-6e-06" iyy="0.051491" iyz="-0.002054" izz="0.033598"/>
    </inertial>
    <visual>
      <origin rpy="0 0 0" xyz="-0.001635 -0.552804 -0.746549"/>
      <geometry>
        <mesh filename="package://HBV2_URDF_description/meshes/Wrist_Theta_1.stl" scale="0.001 0.001 0.001"/>
      </geometry>
      <material name="silver"/>
    </visual>
    <collision>
      <origin rpy="0 0 0" xyz="-0.001635 -0.552804 -0.746549"/>
      <geometry>
        <mesh filename="package://HBV2_URDF_description/meshes/Wrist_Theta_1.stl" scale="0.001 0.001 0.001"/>
      </geometry>
    </collision>
  </link>
  <link name="Gripper_Core_1">
    <inertial>
      <origin rpy="0 0 0" xyz="-0.0003955052408598993 -0.05257449949398196 0.04646356867960444"/>
      <mass value="3.431629449758737"/>
      <inertia ixx="0.009975" ixy="3e-06" ixz="5.2e-05" iyy="0.005271" iyz="-0.000331" izz="0.007649"/>
    </inertial>
    <visual>
      <origin rpy="0 0 0" xyz="-0.001635 -0.555104 -1.048764"/>
      <geometry>
        <mesh filename="package://HBV2_URDF_description/meshes/Gripper_Core_1.stl" scale="0.001 0.001 0.001"/>
      </geometry>
      <material name="silver"/>
    </visual>
    <collision>
      <origin rpy="0 0 0" xyz="-0.001635 -0.555104 -1.048764"/>
      <geometry>
        <mesh filename="package://HBV2_URDF_description/meshes/Gripper_Core_1.stl" scale="0.001 0.001 0.001"/>
      </geometry>
    </collision>
  </link>

  <link name="imu_link"/>
  <joint name="imu_base" type="fixed">
    <origin rpy="0 0 0" xyz="0 0 0"/>
    <parent link="base_link"/>
    <child link="imu_link"/>
  </joint>

  <joint name="Elbow_Theta" type="revolute">
    <origin rpy="0 0 0" xyz="0.0 0.0275 0.258592"/>
    <parent link="Elbow_Theta_1"/>
    <child link="Elbow_Fi_1"/>
    <axis xyz="-0.0 -0.0 -1.0"/>
    <limit effort="100" lower="-1.570796" upper="1.570796" velocity="100"/>
  </joint>
  <joint name="Wrist_Theta" type="revolute">
    <origin rpy="0 0 0" xyz="0.0 -0.0502 0.22926"/>
    <parent link="Wrist_Theta_1"/>
    <child link="Wrist_Fi_1"/>
    <axis xyz="-0.0 -0.0 -1.0"/>
    <limit effort="100" lower="-1.570796" upper="1.570796" velocity="100"/>
  </joint>
  <joint name="Arm_Base" type="fixed">
    <origin rpy="0 0 0" xyz="0.001635 0.496054 0.246551"/>
    <parent link="base_link"/>
    <child link="Shoulder_Theta_1"/>
  </joint>
  <joint name="Shoulder_Theta_Joint" type="revolute">
    <origin rpy="0 0 0" xyz="0.0 0.0 0.072168"/>
    <parent link="Shoulder_Theta_1"/>
    <child link="Shoulder_Fi_1"/>
    <axis xyz="0.0 -0.0 -1.0"/>
    <limit effort="100" lower="-1.570796" upper="1.570796" velocity="100"/>
  </joint>
  <joint name="GCore_RSL" type="revolute">
    <origin rpy="0 0 0" xyz="-0.0141 -0.0655 0.100712"/>
    <parent link="Gripper_Core_1"/>
    <child link="RSL__1__1"/>
    <axis xyz="1.0 0.0 0.0"/>
    <limit effort="100" lower="0.0" upper="1.090831" velocity="100"/>
  </joint>
  <joint name="RSL_RightProng" type="revolute">
    <origin rpy="0 0 0" xyz="-0.0002 0.005315 0.0376"/>
    <parent link="RSL__1__1"/>
    <child link="RightProng__1__1"/>
    <axis xyz="-1.0 -0.0 -0.0"/>
    <limit effort="100" lower="0.0" upper="1.090831" velocity="100"/>
    <mimic joint="GCore_RSL" multiplier="1.0" offset="0.0"/>
  </joint>
  <joint name="LSL_LeftProng" type="revolute">
    <origin rpy="0 0 0" xyz="-0.0002 -0.005315 0.0376"/>
    <parent link="LSL__3__1"/>
    <child link="LeftProng__2__1"/>
    <axis xyz="-1.0 -0.0 -0.0"/>
    <limit effort="100" lower="-1.090831" upper="0.0" velocity="100"/>
    <mimic joint="GCore_RSL" multiplier="-1.0" offset="0.0"/>
  </joint>
  <joint name="GCore_LSL" type="revolute">
    <origin rpy="0 0 0" xyz="-0.0141 -0.0355 0.100712"/>
    <parent link="Gripper_Core_1"/>
    <child link="LSL__3__1"/>
    <axis xyz="1.0 0.0 0.0"/>
    <limit effort="100" lower="-1.090831" upper="0.0" velocity="100"/>
    <mimic joint="GCore_RSL" multiplier="-1.0" offset="0.0"/>
  </joint>
  <joint name="Base_WheelRF" type="continuous">
    <origin rpy="0 0 0" xyz="0.178899 0.266079 0.114299"/>
    <parent link="base_link"/>
    <child link="Wheel_RF_1"/>
    <axis xyz="0.0 -1.0 0.0"/>
  </joint>
  <joint name="Base_WheelLF" type="continuous">
    <origin rpy="0 0 0" xyz="0.178899 0.726029 0.114299"/>
    <parent link="base_link"/>
    <child link="Wheel_LF_1"/>
    <axis xyz="-0.0 1.0 0.0"/>
  </joint>
  <joint name="Base_WheelRB" type="continuous">
    <origin rpy="0 0 0" xyz="-0.175629 0.266079 0.114299"/>
    <parent link="base_link"/>
    <child link="Wheel_RB_1"/>
    <axis xyz="-0.0 -1.0 0.0"/>
  </joint>
  <joint name="Base_WheelLB" type="continuous">
    <origin rpy="0 0 0" xyz="-0.175629 0.726029 0.114299"/>
    <parent link="base_link"/>
    <child link="Wheel_LB_1"/>
    <axis xyz="0.0 1.0 0.0"/>
  </joint>
  <joint name="Base_CameraRod" type="fixed">
    <origin rpy="0 0 0" xyz="-0.316947 1e-06 0.0064"/>
    <parent link="Shoulder_Theta_1"/>
    <child link="Camera_Rod__1__1"/>
  </joint>
  <joint name="CameraRod_CameraHousing" type="fixed">
    <origin rpy="0 0 0" xyz="0.0 0.0 0.4"/>
    <parent link="Camera_Rod__1__1"/>
    <child link="Camera_Housing_1"/>
  </joint>
  <joint name="Shoulder_Fi" type="revolute">
    <origin rpy="0 0 0" xyz="0.0 -0.0275 0.090554"/>
    <parent link="Shoulder_Fi_1"/>
    <child link="Elbow_Theta_1"/>
    <axis xyz="0.0 1.0 -0.0"/>
    <limit effort="100" lower="0.0" upper="1.396263" velocity="100"/>
  </joint>
  <joint name="Elbow_Fi" type="revolute">
    <origin rpy="0 0 0" xyz="0.0 0.05675 0.078684"/>
    <parent link="Elbow_Fi_1"/>
    <child link="Wrist_Theta_1"/>
    <axis xyz="0.0 1.0 -0.0"/>
    <limit effort="100" lower="-1.396263" upper="1.396263" velocity="100"/>
  </joint>
  <joint name="Wrist_Fi" type="revolute">
    <origin rpy="0 0 0" xyz="0.0 0.0525 0.072955"/>
    <parent link="Wrist_Fi_1"/>
    <child link="Gripper_Core_1"/>
    <axis xyz="0.0 1.0 -0.0"/>
    <limit effort="100" lower="-1.570796" upper="1.570796" velocity="100"/>
  </joint>
</robot>
