<?xml version="1.0" ?>
<!-- =================================================================================== -->
<!-- |    This document was autogenerated by xacro from HBV2_URDF.xacro                | -->
<!-- |    EDITING THIS FILE BY HAND IS NOT RECOMMENDED                                 | -->
<!-- =================================================================================== -->
<robot name="base">
    <material name="silver">
        <color rgba="0.700 0.700 0.700 1.000"/>
    </material>

    <transmission name="Base_WheelRF_tran">
    <type>transmission_interface/SimpleTransmission</type>
    <joint name="Base_WheelRF">
        <hardwareInterface>hardware_interface/VelocityJointInterface</hardwareInterface>
    </joint>
    <actuator name="Base_WheelRF_actr">
        <hardwareInterface>hardware_interface/VelocityJointInterface</hardwareInterface>
        <mechanicalReduction>1</mechanicalReduction>
    </actuator>
    </transmission>
    <transmission name="Base_WheelLF_tran">
    <type>transmission_interface/SimpleTransmission</type>
    <joint name="Base_WheelLF">
        <hardwareInterface>hardware_interface/VelocityJointInterface</hardwareInterface>
    </joint>
    <actuator name="Base_WheelLF_actr">
        <hardwareInterface>hardware_interface/VelocityJointInterface</hardwareInterface>
        <mechanicalReduction>1</mechanicalReduction>
    </actuator>
    </transmission>
    <transmission name="Base_WheelRB_tran">
    <type>transmission_interface/SimpleTransmission</type>
    <joint name="Base_WheelRB">
        <hardwareInterface>hardware_interface/VelocityJointInterface</hardwareInterface>
    </joint>
    <actuator name="Base_WheelRB_actr">
        <hardwareInterface>hardware_interface/VelocityJointInterface</hardwareInterface>
        <mechanicalReduction>1</mechanicalReduction>
    </actuator>
    </transmission>
    <transmission name="Base_WheelLB_tran">
    <type>transmission_interface/SimpleTransmission</type>
    <joint name="Base_WheelLB">
        <hardwareInterface>hardware_interface/VelocityJointInterface</hardwareInterface>
    </joint>
    <actuator name="Base_WheelLB_actr">
        <hardwareInterface>hardware_interface/VelocityJointInterface</hardwareInterface>
        <mechanicalReduction>1</mechanicalReduction>
    </actuator>
    </transmission>
    <gazebo>
        <plugin filename="libgazebo_ros_control.so" name="control"/>
    </gazebo>

    <gazebo reference="base_link">
        <material>Gazebo/Silver</material>
        <mu1>0.2</mu1>
        <mu2>0.2</mu2>
        <selfCollide>true</selfCollide>
        <gravity>true</gravity>
    </gazebo>

    <gazebo reference="Wheel_RF_1">
        <material>Gazebo/Silver</material>
        <mu1>0.2</mu1>
        <mu2>0.2</mu2>
        <selfCollide>true</selfCollide>
    </gazebo>
    <gazebo reference="Wheel_LF_1">
        <material>Gazebo/Silver</material>
        <mu1>0.2</mu1>
        <mu2>0.2</mu2>
        <selfCollide>true</selfCollide>
    </gazebo>
    <gazebo reference="Wheel_RB_1">
        <material>Gazebo/Silver</material>
        <mu1>0.2</mu1>
        <mu2>0.2</mu2>
        <selfCollide>true</selfCollide>
    </gazebo>
    <gazebo reference="Wheel_LB_1">
        <material>Gazebo/Silver</material>
        <mu1>0.2</mu1>
        <mu2>0.2</mu2>
        <selfCollide>true</selfCollide>
    </gazebo>
    <gazebo reference="Camera_Rod__1__1">
        <material>Gazebo/Silver</material>
        <mu1>0.2</mu1>
        <mu2>0.2</mu2>
        <selfCollide>true</selfCollide>
    </gazebo>
    <gazebo reference="Camera_Housing_1">
        <material>Gazebo/Silver</material>
        <mu1>0.2</mu1>
        <mu2>0.2</mu2>
        <selfCollide>true</selfCollide>
    </gazebo>

    <link name="base_link">
        <inertial>
          <origin rpy="0 0 0" xyz="0.000850703825743988 0.49664524660197173 0.1431193454180441"/>
          <mass value="83.16735088772546"/>
          <inertia ixx="2.05207" ixy="-0.008757" ixz="0.001707" iyy="3.182622" iyz="0.00132" izz="4.445124"/>
        </inertial>
        <visual>
          <origin rpy="0 0 0" xyz="0 0 0"/>
          <geometry>
            <mesh filename="package://HBV2_URDF_description/meshes/base_link.stl" scale="0.001 0.001 0.001"/>
          </geometry>
          <material name="silver"/>
        </visual>
        <collision>
          <origin rpy="0 0 0" xyz="0 0 0"/>
          <geometry>
            <mesh filename="package://HBV2_URDF_description/meshes/base_link.stl" scale="0.001 0.001 0.001"/>
          </geometry>
        </collision>
      </link>

      <link name="Wheel_RF_1">
        <inertial>
          <origin rpy="0 0 0" xyz="1.0816852191730675e-08 -0.02075000000044916 2.772021913399758e-07"/>
          <mass value="21.410160340290883"/>
          <inertia ixx="0.079808" ixy="-0.0" ixz="0.0" iyy="0.140288" iyz="0.0" izz="0.079808"/>
        </inertial>
        <visual>
          <origin rpy="0 0 0" xyz="-0.178899 -0.266079 -0.114299"/>
          <geometry>
            <mesh filename="package://HBV2_URDF_description/meshes/Wheel_RF_1.stl" scale="0.001 0.001 0.001"/>
          </geometry>
          <material name="silver"/>
        </visual>
        <collision>
          <origin rpy="0 0 0" xyz="-0.178899 -0.266079 -0.114299"/>
          <geometry>
            <mesh filename="package://HBV2_URDF_description/meshes/Wheel_RF_1.stl" scale="0.001 0.001 0.001"/>
          </geometry>
        </collision>
      </link>
      <link name="Wheel_LF_1">
        <inertial>
          <origin rpy="0 0 0" xyz="1.0816852247241826e-08 0.0207499999995574 2.772021904656752e-07"/>
          <mass value="21.410160340290883"/>
          <inertia ixx="0.079808" ixy="-0.0" ixz="0.0" iyy="0.140288" iyz="0.0" izz="0.079808"/>
        </inertial>
        <visual>
          <origin rpy="0 0 0" xyz="-0.178899 -0.726029 -0.114299"/>
          <geometry>
            <mesh filename="package://HBV2_URDF_description/meshes/Wheel_LF_1.stl" scale="0.001 0.001 0.001"/>
          </geometry>
          <material name="silver"/>
        </visual>
        <collision>
          <origin rpy="0 0 0" xyz="-0.178899 -0.726029 -0.114299"/>
          <geometry>
            <mesh filename="package://HBV2_URDF_description/meshes/Wheel_LF_1.stl" scale="0.001 0.001 0.001"/>
          </geometry>
        </collision>
      </link>
      <link name="Wheel_RB_1">
        <inertial>
          <origin rpy="0 0 0" xyz="4.974939914748067e-07 -0.020750000000448382 2.7720219129834245e-07"/>
          <mass value="21.410160340290883"/>
          <inertia ixx="0.079808" ixy="-0.0" ixz="0.0" iyy="0.140288" iyz="-0.0" izz="0.079808"/>
        </inertial>
        <visual>
          <origin rpy="0 0 0" xyz="0.175629 -0.266079 -0.114299"/>
          <geometry>
            <mesh filename="package://HBV2_URDF_description/meshes/Wheel_RB_1.stl" scale="0.001 0.001 0.001"/>
          </geometry>
          <material name="silver"/>
        </visual>
        <collision>
          <origin rpy="0 0 0" xyz="0.175629 -0.266079 -0.114299"/>
          <geometry>
            <mesh filename="package://HBV2_URDF_description/meshes/Wheel_RB_1.stl" scale="0.001 0.001 0.001"/>
          </geometry>
        </collision>
      </link>
      <link name="Wheel_LB_1">
        <inertial>
          <origin rpy="0 0 0" xyz="4.974939914470511e-07 0.020749999999557622 2.772021902019972e-07"/>
          <mass value="21.410160340290883"/>
          <inertia ixx="0.079808" ixy="-0.0" ixz="0.0" iyy="0.140288" iyz="-0.0" izz="0.079808"/>
        </inertial>
        <visual>
          <origin rpy="0 0 0" xyz="0.175629 -0.726029 -0.114299"/>
          <geometry>
            <mesh filename="package://HBV2_URDF_description/meshes/Wheel_LB_1.stl" scale="0.001 0.001 0.001"/>
          </geometry>
          <material name="silver"/>
        </visual>
        <collision>
          <origin rpy="0 0 0" xyz="0.175629 -0.726029 -0.114299"/>
          <geometry>
            <mesh filename="package://HBV2_URDF_description/meshes/Wheel_LB_1.stl" scale="0.001 0.001 0.001"/>
          </geometry>
        </collision>
      </link>
      <link name="Camera_Rod__1__1">
        <inertial>
          <origin rpy="0 0 0" xyz="-4.99966369915672e-07 -1.0508501291361938e-09 0.19999953386361996"/>
          <mass value="1.327380701446504"/>
          <inertia ixx="0.017743" ixy="-0.0" ixz="0.0" iyy="0.017743" iyz="0.0" izz="8.9e-05"/>
        </inertial>
        <visual>
          <origin rpy="0 0 0" xyz="0.315312 -0.496055 -0.252951"/>
          <geometry>
            <mesh filename="package://HBV2_URDF_description/meshes/Camera_Rod__1__1.stl" scale="0.001 0.001 0.001"/>
          </geometry>
          <material name="silver"/>
        </visual>
        <collision>
          <origin rpy="0 0 0" xyz="0.315312 -0.496055 -0.252951"/>
          <geometry>
            <mesh filename="package://HBV2_URDF_description/meshes/Camera_Rod__1__1.stl" scale="0.001 0.001 0.001"/>
          </geometry>
        </collision>
      </link>
      <link name="Camera_Housing_1">
        <inertial>
          <origin rpy="0 0 0" xyz="-0.0010156886248149921 3.0852436220807355e-06 0.00711860710983836"/>
          <mass value="1.3677782029205452"/>
          <inertia ixx="0.00192" ixy="-0.0" ixz="1.3e-05" iyy="0.000885" iyz="-0.0" izz="0.001671"/>
        </inertial>
        <visual>
          <origin rpy="0 0 0" xyz="0.315312 -0.496055 -0.652951"/>
          <geometry>
            <mesh filename="package://HBV2_URDF_description/meshes/Camera_Housing_1.stl" scale="0.001 0.001 0.001"/>
          </geometry>
          <material name="silver"/>
        </visual>
        <collision>
          <origin rpy="0 0 0" xyz="0.315312 -0.496055 -0.652951"/>
          <geometry>
            <mesh filename="package://HBV2_URDF_description/meshes/Camera_Housing_1.stl" scale="0.001 0.001 0.001"/>
          </geometry>
        </collision>
      </link>

      <joint name="Base_WheelRF" type="continuous">
        <origin rpy="0 0 0" xyz="0.178899 0.266079 0.114299"/>
        <parent link="base_link"/>
        <child link="Wheel_RF_1"/>
        <axis xyz="0.0 -1.0 0.0"/>
      </joint>
      <joint name="Base_WheelLF" type="continuous">
        <origin rpy="0 0 0" xyz="0.178899 0.726029 0.114299"/>
        <parent link="base_link"/>
        <child link="Wheel_LF_1"/>
        <axis xyz="-0.0 1.0 0.0"/>
      </joint>
      <joint name="Base_WheelRB" type="continuous">
        <origin rpy="0 0 0" xyz="-0.175629 0.266079 0.114299"/>
        <parent link="base_link"/>
        <child link="Wheel_RB_1"/>
        <axis xyz="-0.0 -1.0 0.0"/>
      </joint>
      <joint name="Base_WheelLB" type="continuous">
        <origin rpy="0 0 0" xyz="-0.175629 0.726029 0.114299"/>
        <parent link="base_link"/>
        <child link="Wheel_LB_1"/>
        <axis xyz="0.0 1.0 0.0"/>
      </joint>
      <joint name="Base_CameraRod" type="fixed">
        <origin rpy="0 0 0" xyz="-0.316947 1e-06 0.0064"/>
        <parent link="Shoulder_Theta_1"/>
        <child link="Camera_Rod__1__1"/>
      </joint>
      <joint name="CameraRod_CameraHousing" type="fixed">
        <origin rpy="0 0 0" xyz="0.0 0.0 0.4"/>
        <parent link="Camera_Rod__1__1"/>
        <child link="Camera_Housing_1"/>
      </joint>

      </robot>